Traceback (most recent call last):
  File "/Users/usiusi/Documents/Repositories/Craftdroid/craft_custom/venv/lib/python3.7/site-packages/urllib3/connection.py", line 160, in _new_conn
    (self._dns_host, self.port), self.timeout, **extra_kw
  File "/Users/usiusi/Documents/Repositories/Craftdroid/craft_custom/venv/lib/python3.7/site-packages/urllib3/util/connection.py", line 84, in create_connection
    raise err
  File "/Users/usiusi/Documents/Repositories/Craftdroid/craft_custom/venv/lib/python3.7/site-packages/urllib3/util/connection.py", line 74, in create_connection
    sock.connect(sa)
ConnectionRefusedError: [Errno 61] Connection refused

During handling of the above exception, another exception occurred:

Traceback (most recent call last):
  File "/Users/usiusi/Documents/Repositories/Craftdroid/craft_custom/venv/lib/python3.7/site-packages/urllib3/connectionpool.py", line 677, in urlopen
    chunked=chunked,
  File "/Users/usiusi/Documents/Repositories/Craftdroid/craft_custom/venv/lib/python3.7/site-packages/urllib3/connectionpool.py", line 392, in _make_request
    conn.request(method, url, **httplib_request_kw)
  File "/Library/Frameworks/Python.framework/Versions/3.7/lib/python3.7/http/client.py", line 1229, in request
    self._send_request(method, url, body, headers, encode_chunked)
  File "/Library/Frameworks/Python.framework/Versions/3.7/lib/python3.7/http/client.py", line 1275, in _send_request
    self.endheaders(body, encode_chunked=encode_chunked)
  File "/Library/Frameworks/Python.framework/Versions/3.7/lib/python3.7/http/client.py", line 1224, in endheaders
    self._send_output(message_body, encode_chunked=encode_chunked)
  File "/Library/Frameworks/Python.framework/Versions/3.7/lib/python3.7/http/client.py", line 1016, in _send_output
    self.send(msg)
  File "/Library/Frameworks/Python.framework/Versions/3.7/lib/python3.7/http/client.py", line 956, in send
    self.connect()
  File "/Users/usiusi/Documents/Repositories/Craftdroid/craft_custom/venv/lib/python3.7/site-packages/urllib3/connection.py", line 187, in connect
    conn = self._new_conn()
  File "/Users/usiusi/Documents/Repositories/Craftdroid/craft_custom/venv/lib/python3.7/site-packages/urllib3/connection.py", line 172, in _new_conn
    self, "Failed to establish a new connection: %s" % e
urllib3.exceptions.NewConnectionError: <urllib3.connection.HTTPConnection object at 0x7fb17d950860>: Failed to establish a new connection: [Errno 61] Connection refused

During handling of the above exception, another exception occurred:

Traceback (most recent call last):
  File "/Users/usiusi/Documents/Repositories/Craftdroid/craft_custom/Explorer.py", line 584, in start
    explorer = Explorer(config_id, appium_port, udid, logfile)
  File "/Users/usiusi/Documents/Repositories/Craftdroid/craft_custom/Explorer.py", line 30, in __init__
    self.src_events, self.src_labels = Util.load_events(self.config.id, 'base_from')
  File "/Users/usiusi/Documents/Repositories/Craftdroid/craft_custom/Util.py", line 110, in load_events
    src_events = Util.run_source_test(fpath)
  File "/Users/usiusi/Documents/Repositories/Craftdroid/craft_custom/Util.py", line 101, in run_source_test
    extractor = CraftdroidExtractor(file)
  File "/Users/usiusi/Documents/Repositories/Craftdroid/craft_custom/test_attribute_extractor/test_attribute_extractor.py", line 23, in __init__
    self.driver = self.check_run_possible(self.app_package, caps)
  File "/Users/usiusi/Documents/Repositories/Craftdroid/craft_custom/test_attribute_extractor/test_attribute_extractor.py", line 49, in check_run_possible
    driver = webdriver.Remote('http://localhost:4723/wd/hub', caps)
  File "/Users/usiusi/Documents/Repositories/Craftdroid/craft_custom/venv/lib/python3.7/site-packages/appium/webdriver/webdriver.py", line 151, in __init__
    proxy
  File "/Users/usiusi/Documents/Repositories/Craftdroid/craft_custom/venv/lib/python3.7/site-packages/selenium/webdriver/remote/webdriver.py", line 157, in __init__
    self.start_session(capabilities, browser_profile)
  File "/Users/usiusi/Documents/Repositories/Craftdroid/craft_custom/venv/lib/python3.7/site-packages/appium/webdriver/webdriver.py", line 227, in start_session
    response = self.execute(RemoteCommand.NEW_SESSION, parameters)
  File "/Users/usiusi/Documents/Repositories/Craftdroid/craft_custom/venv/lib/python3.7/site-packages/selenium/webdriver/remote/webdriver.py", line 319, in execute
    response = self.command_executor.execute(driver_command, params)
  File "/Users/usiusi/Documents/Repositories/Craftdroid/craft_custom/venv/lib/python3.7/site-packages/selenium/webdriver/remote/remote_connection.py", line 374, in execute
    return self._request(command_info[0], url, body=data)
  File "/Users/usiusi/Documents/Repositories/Craftdroid/craft_custom/venv/lib/python3.7/site-packages/selenium/webdriver/remote/remote_connection.py", line 397, in _request
    resp = self._conn.request(method, url, body=body, headers=headers)
  File "/Users/usiusi/Documents/Repositories/Craftdroid/craft_custom/venv/lib/python3.7/site-packages/urllib3/request.py", line 80, in request
    method, url, fields=fields, headers=headers, **urlopen_kw
  File "/Users/usiusi/Documents/Repositories/Craftdroid/craft_custom/venv/lib/python3.7/site-packages/urllib3/request.py", line 171, in request_encode_body
    return self.urlopen(method, url, **extra_kw)
  File "/Users/usiusi/Documents/Repositories/Craftdroid/craft_custom/venv/lib/python3.7/site-packages/urllib3/poolmanager.py", line 336, in urlopen
    response = conn.urlopen(method, u.request_uri, **kw)
  File "/Users/usiusi/Documents/Repositories/Craftdroid/craft_custom/venv/lib/python3.7/site-packages/urllib3/connectionpool.py", line 765, in urlopen
    **response_kw
  File "/Users/usiusi/Documents/Repositories/Craftdroid/craft_custom/venv/lib/python3.7/site-packages/urllib3/connectionpool.py", line 765, in urlopen
    **response_kw
  File "/Users/usiusi/Documents/Repositories/Craftdroid/craft_custom/venv/lib/python3.7/site-packages/urllib3/connectionpool.py", line 765, in urlopen
    **response_kw
  File "/Users/usiusi/Documents/Repositories/Craftdroid/craft_custom/venv/lib/python3.7/site-packages/urllib3/connectionpool.py", line 725, in urlopen
    method, url, error=e, _pool=self, _stacktrace=sys.exc_info()[2]
  File "/Users/usiusi/Documents/Repositories/Craftdroid/craft_custom/venv/lib/python3.7/site-packages/urllib3/util/retry.py", line 439, in increment
    raise MaxRetryError(_pool, url, error or ResponseError(cause))
urllib3.exceptions.MaxRetryError: HTTPConnectionPool(host='localhost', port=4723): Max retries exceeded with url: /wd/hub/session (Caused by NewConnectionError('<urllib3.connection.HTTPConnection object at 0x7fb17d950860>: Failed to establish a new connection: [Errno 61] Connection refused'))
