Traceback (most recent call last):
  File "/Users/usiusi/Documents/Repositories/Craftdroid/craft_custom/Explorer.py", line 584, in start
    explorer = Explorer(config_id, appium_port, udid, logfile)
  File "/Users/usiusi/Documents/Repositories/Craftdroid/craft_custom/Explorer.py", line 30, in __init__
    self.src_events, self.src_labels = Util.load_events(self.config.id, 'base_from')
  File "/Users/usiusi/Documents/Repositories/Craftdroid/craft_custom/Util.py", line 110, in load_events
    src_events = Util.run_source_test(fpath)
  File "/Users/usiusi/Documents/Repositories/Craftdroid/craft_custom/Util.py", line 101, in run_source_test
    extractor = CraftdroidExtractor(file)
  File "/Users/usiusi/Documents/Repositories/Craftdroid/craft_custom/test_attribute_extractor/test_attribute_extractor.py", line 21, in __init__
    self.logger = self.get_logger(log_address)
  File "/Users/usiusi/Documents/Repositories/Craftdroid/craft_custom/test_attribute_extractor/test_attribute_extractor.py", line 33, in get_logger
    fh = logging.FileHandler(os.path.join(config.logs_dir, name), mode='w')
  File "/Library/Frameworks/Python.framework/Versions/3.7/lib/python3.7/logging/__init__.py", line 1092, in __init__
    StreamHandler.__init__(self, self._open())
  File "/Library/Frameworks/Python.framework/Versions/3.7/lib/python3.7/logging/__init__.py", line 1121, in _open
    return open(self.baseFilename, self.mode, encoding=self.encoding)
FileNotFoundError: [Errno 2] No such file or directory: '/data/output/logs/craftdroid_tests/b22_a24_log.txt'
