Traceback (most recent call last):
  File "/Users/usiusi/Documents/Repositories/Craftdroid/craft_custom/Runner.py", line 130, in perform_actions
    WebDriverWait(self.driver, wait_time).until(EC.presence_of_element_located(locator))
  File "/Users/usiusi/Documents/Repositories/Craftdroid/craft_custom/venv/lib/python3.7/site-packages/selenium/webdriver/support/wait.py", line 80, in until
    raise TimeoutException(message, screen, stacktrace)
selenium.common.exceptions.TimeoutException: Message: 


During handling of the above exception, another exception occurred:

Traceback (most recent call last):
  File "/Users/usiusi/Documents/Repositories/Craftdroid/craft_custom/Explorer.py", line 184, in run
    match = self.check_reachability(w, pkg, act)
  File "/Users/usiusi/Documents/Repositories/Craftdroid/craft_custom/Explorer.py", line 382, in check_reachability
    match = self.validate_path(ppath, w, invalid_paths)
  File "/Users/usiusi/Documents/Repositories/Craftdroid/craft_custom/Explorer.py", line 407, in validate_path
    _, __, ___ = self.execute_target_events([])
  File "/Users/usiusi/Documents/Repositories/Craftdroid/craft_custom/Explorer.py", line 338, in execute_target_events
    self.runner.perform_actions(self.tgt_events, require_wait, reset=True, cgp=self.cgp)
  File "/Users/usiusi/Documents/Repositories/Craftdroid/craft_custom/Runner.py", line 141, in perform_actions
    assert False, "Failed WAIT_UNTIL action"
AssertionError: Failed WAIT_UNTIL action
