Traceback (most recent call last):
  File "/Users/usiusi/Documents/Repositories/Craftdroid/craft_custom/venv/lib/python3.7/site-packages/urllib3/connectionpool.py", line 677, in urlopen
    chunked=chunked,
  File "/Users/usiusi/Documents/Repositories/Craftdroid/craft_custom/venv/lib/python3.7/site-packages/urllib3/connectionpool.py", line 426, in _make_request
    six.raise_from(e, None)
  File "<string>", line 3, in raise_from
  File "/Users/usiusi/Documents/Repositories/Craftdroid/craft_custom/venv/lib/python3.7/site-packages/urllib3/connectionpool.py", line 421, in _make_request
    httplib_response = conn.getresponse()
  File "/Library/Frameworks/Python.framework/Versions/3.7/lib/python3.7/http/client.py", line 1321, in getresponse
    response.begin()
  File "/Library/Frameworks/Python.framework/Versions/3.7/lib/python3.7/http/client.py", line 296, in begin
    version, status, reason = self._read_status()
  File "/Library/Frameworks/Python.framework/Versions/3.7/lib/python3.7/http/client.py", line 265, in _read_status
    raise RemoteDisconnected("Remote end closed connection without"
http.client.RemoteDisconnected: Remote end closed connection without response

During handling of the above exception, another exception occurred:

Traceback (most recent call last):
  File "/Users/usiusi/Documents/Repositories/Craftdroid/craft_custom/venv/lib/python3.7/site-packages/requests/adapters.py", line 449, in send
    timeout=timeout
  File "/Users/usiusi/Documents/Repositories/Craftdroid/craft_custom/venv/lib/python3.7/site-packages/urllib3/connectionpool.py", line 725, in urlopen
    method, url, error=e, _pool=self, _stacktrace=sys.exc_info()[2]
  File "/Users/usiusi/Documents/Repositories/Craftdroid/craft_custom/venv/lib/python3.7/site-packages/urllib3/util/retry.py", line 403, in increment
    raise six.reraise(type(error), error, _stacktrace)
  File "/Users/usiusi/Documents/Repositories/Craftdroid/craft_custom/venv/lib/python3.7/site-packages/urllib3/packages/six.py", line 734, in reraise
    raise value.with_traceback(tb)
  File "/Users/usiusi/Documents/Repositories/Craftdroid/craft_custom/venv/lib/python3.7/site-packages/urllib3/connectionpool.py", line 677, in urlopen
    chunked=chunked,
  File "/Users/usiusi/Documents/Repositories/Craftdroid/craft_custom/venv/lib/python3.7/site-packages/urllib3/connectionpool.py", line 426, in _make_request
    six.raise_from(e, None)
  File "<string>", line 3, in raise_from
  File "/Users/usiusi/Documents/Repositories/Craftdroid/craft_custom/venv/lib/python3.7/site-packages/urllib3/connectionpool.py", line 421, in _make_request
    httplib_response = conn.getresponse()
  File "/Library/Frameworks/Python.framework/Versions/3.7/lib/python3.7/http/client.py", line 1321, in getresponse
    response.begin()
  File "/Library/Frameworks/Python.framework/Versions/3.7/lib/python3.7/http/client.py", line 296, in begin
    version, status, reason = self._read_status()
  File "/Library/Frameworks/Python.framework/Versions/3.7/lib/python3.7/http/client.py", line 265, in _read_status
    raise RemoteDisconnected("Remote end closed connection without"
urllib3.exceptions.ProtocolError: ('Connection aborted.', RemoteDisconnected('Remote end closed connection without response'))

During handling of the above exception, another exception occurred:

Traceback (most recent call last):
  File "/Users/usiusi/Documents/Repositories/Craftdroid/craft_custom/Explorer.py", line 585, in start
    is_done, failed_step = explorer.run()
  File "/Users/usiusi/Documents/Repositories/Craftdroid/craft_custom/Explorer.py", line 153, in run
    self.src_labels[self.current_src_index])
  File "/Users/usiusi/Documents/Repositories/Craftdroid/craft_custom/WidgetUtil.py", line 303, in most_similar
    similars = WidgetUtil.score_widgets(src_event, actionable_widget, target_labels, src_labels)
  File "/Users/usiusi/Documents/Repositories/Craftdroid/craft_custom/WidgetUtil.py", line 313, in score_widgets
    addFileNameToMatchObject(match_object)
  File "/Users/usiusi/Documents/Repositories/Craftdroid/craft_custom/widget_process/file_name_adder.py", line 105, in addFileNameToMatchObject
    TargetFileNameAdder.add_file_name_to_widgets(m_obj.candidates_map.values())
  File "/Users/usiusi/Documents/Repositories/Craftdroid/craft_custom/widget_process/file_name_adder.py", line 66, in add_file_name_to_widgets
    best_activity = cls._find_best_activity(w['activity'], list(results.keys()))
  File "/Users/usiusi/Documents/Repositories/Craftdroid/craft_custom/widget_process/file_name_adder.py", line 76, in _find_best_activity
    scored_indexes = send_object(match_object.get_json())
  File "/Users/usiusi/Documents/Repositories/Craftdroid/craft_custom/matching_client/object_sender.py", line 6, in send_object
    resp = requests.post(url='http://127.0.0.1:5000/ranking', json=math_object).json()
  File "/Users/usiusi/Documents/Repositories/Craftdroid/craft_custom/venv/lib/python3.7/site-packages/requests/api.py", line 119, in post
    return request('post', url, data=data, json=json, **kwargs)
  File "/Users/usiusi/Documents/Repositories/Craftdroid/craft_custom/venv/lib/python3.7/site-packages/requests/api.py", line 61, in request
    return session.request(method=method, url=url, **kwargs)
  File "/Users/usiusi/Documents/Repositories/Craftdroid/craft_custom/venv/lib/python3.7/site-packages/requests/sessions.py", line 530, in request
    resp = self.send(prep, **send_kwargs)
  File "/Users/usiusi/Documents/Repositories/Craftdroid/craft_custom/venv/lib/python3.7/site-packages/requests/sessions.py", line 643, in send
    r = adapter.send(request, **kwargs)
  File "/Users/usiusi/Documents/Repositories/Craftdroid/craft_custom/venv/lib/python3.7/site-packages/requests/adapters.py", line 498, in send
    raise ConnectionError(err, request=request)
requests.exceptions.ConnectionError: ('Connection aborted.', RemoteDisconnected('Remote end closed connection without response'))
